Workbook

Sheet Cover & Instructions
B2: The Hershey Company (NYSE: HSY)
B3: Financial Model Workbook — DCF, LBO & Historical Analysis Template
B5: Company | C5: The Hershey Company
B6: Ticker / Exchange | C6: HSY / NYSE
B7: Sector / Industry | C7: Consumer Staples — Packaged Foods & Confectionery
B8: Fiscal Year End | C8: December 31 (52/53-week fiscal year)
B9: Market data as of | C9: September 18, 2026
B10: Company selected | C10: Randomly selected large-cap public company, per your request
B12: What's in this workbook
B13: Assumptions & Market Data | C13: Current price, shares, market cap, net debt, and the raw cost-of-capital inputs (risk-free rate, beta) a WACC build needs.
B14: Income Statement | C14: FY2022–FY2025 actual net sales, COGS, SG&A, interest, taxes and net income, sourced from Hershey's 10-K / earnings releases.
B15: Balance Sheet | C15: FY2023–FY2025 actual assets, liabilities and equity.
B16: Cash Flow Statement | C16: FY2022–FY2025 actual operating, investing and financing cash flows, incl. D&A and capex — the key DCF build blocks.
B17: DCF Model | C17: 5-year unlevered FCF build and a Gordon Growth / Exit Multiple terminal value bridge to implied share price. Formulas are pre-built; growth, margin, WACC and terminal-value assumptions are blank for you to enter.
B18: LBO Model | C18: Sources & uses, a 5-year debt paydown schedule, and a returns (MOIC / IRR) build. Formulas are pre-built; entry/exit multiples, leverage, pricing and operating assumptions are blank for you to enter.
B20: How to use this workbook
B21: Blue text | C21: Hardcoded historical actuals or market data, pulled from a cited source. Do not need to be changed.
B22: Black text | C22: Live formulas (subtotals, statement math, and the DCF/LBO calculation engine). These recalculate automatically as you fill in the yellow cells.
B23: Green text | C23: A formula that links to another tab (e.g., DCF pulling FY2025 revenue from the Income Statement tab).
B24: Yellow fill | C24: Blank on purpose — this is where YOU enter an assumption or calculate a margin/ratio. Cell comments (small red triangle) give a hint on what belongs there.
B26: What's intentionally left blank
B27: • | C27: All margin & ratio analysis on the historical statements: gross margin, operating margin, EBITDA margin, net margin, effective tax rate, YoY growth rates, FCF margin/conversion, current ratio, and leverage ratios (Debt/EBITDA, Net Debt/EBITDA, Debt/Equity).
B29: • | C29: All DCF assumptions: revenue growth, EBITDA margin, D&A %, capex %, change-in-NWC %, cost of equity/debt, WACC, terminal growth rate, and exit multiple.
B31: • | C31: All LBO assumptions: entry & exit EV/EBITDA multiples, leverage (Debt/EBITDA), interest rate, mandatory amortization %, cash sweep %, EBITDA growth, capex %, and exit year.
B34: Sources
B35: • | C35: Hershey FY2025 & FY2024 results: PR Newswire, "Hershey Reports Fourth-Quarter and Full-Year 2025 Financial Results" (Feb 2026), prnewswire.com
B36: • | C36: Hershey FY2023 & FY2022 results: PR Newswire, "Hershey Reports Fourth-Quarter and Full-Year 2023 Financial Results" (Feb 2024), prnewswire.com
B37: • | C37: Balance sheet & cash flow detail (FY2022–FY2025): stockanalysis.com/stocks/HSY/financials/
B38: • | C38: Market price, shares outstanding, beta: stockanalysis.com/stocks/hsy/ (as of 9/18/2026 close)
B39: • | C39: 10-Year U.S. Treasury yield: tradingeconomics.com/united-states/government-bond-yield (9/18/2026)
B40: • | C40: Full audited statements: Hershey Company Form 10-K, SEC EDGAR (sec.gov/cgi-bin/browse-edgar?action=getcompany&CIK=0000047111)
B42: Note | C42: Figures are aggregated from secondary sources (press releases and financial data aggregators), not retyped directly from the 10-K line by line, so a few totals may be off from the audited statements by a small rounding amount (well under 1%). Verify against the 10-K/EDGAR filing before using in anything client-facing.

Sheet Assumptions
B2: Assumptions & Market Data
B3: $ in millions except per-share data, multiples, and percentages
B5: Market Data (as of 9/18/2026 close)
B6: Current Share Price | C6: 169.79 | E6: Source: stockanalysis.com/stocks/hsy/, 9/18/2026 close
B7: Basic Shares Outstanding (current) | C7: 200.93 | E7: Source: stockanalysis.com/stocks/hsy/
B8: Diluted Weighted-Avg Shares (FY2025A) | C8: 203.4 | E8: Source: Hershey FY2025 earnings release (PR Newswire, Feb 2026)
B9: Market Capitalization | C9: =C6*C7 -> 34115.905
B10: Dividend per Share (LTM) | C10: 5.81 | E10: Source: stockanalysis.com/stocks/hsy/
B12: Net Debt (Enterprise Value Bridge)
B13: Total Debt (FY2025A: ST + LT debt) | C13: ='Balance Sheet'!E20+'Balance Sheet'!E23 -> 4830.55
B14: Less: Cash & Equivalents (FY2025A) | C14: ='Balance Sheet'!E7 -> 925.86
B15: Net Debt | C15: =C13-C14 -> 3904.69
B16: Enterprise Value (current, implied) | C16: =C9+C15 -> 38020.595
B18: Cost of Capital Inputs
B19: Risk-Free Rate (10-Yr U.S. Treasury) | C19: 0.05 | E19: Source: tradingeconomics.com, 10-yr UST yield, 9/18/2026
B20: Beta (5Y vs. S&P 500) | C20: 0.45 | E20: Source: stockanalysis.com. NOTE: this reads low for the sector (peers ~0.3-0.6) - cross-check vs. Bloomberg/CapIQ or a peer average before relying on it.
B21: Equity Risk Premium (ERP) | C21: 0.0425
B22: Cost of Equity (CAPM = Rf + β × ERP) | C22: =C19+(C21*C20) -> 0.069125
B23: Pre-Tax Cost of Debt | C23: ='Income Statement'!F14/'Balance Sheet'!E37 -> 0.039374398
B24: Marginal / Statutory Tax Rate (for WACC & projections) | C24: 0.165
B25: After-Tax Cost of Debt | C25: =C23*(1-C24) -> 0.032877623
B26: Weight of Equity (E / (D+E)) | C26: =(C9)/(C9+C13) -> 0.87596946
B27: Weight of Debt (D / (D+E)) | C27: =C13/(C9+C13) -> 0.12403054
B28: WACC | C28: =(C27*C25)+(C26*C22) -> 0.064629218

Sheet Income Statement
B2: Income Statement — Historical Actuals
B3: $ in millions except per-share data. FY = fiscal year ended December 31.
C5: FY2022A | D5: FY2023A | E5: FY2024A | F5: FY2025A
B6: Net Sales | C6: 10419.294 | D6: 11164.992 | E6: 11202.3 | F6: 11692.6
B7: Cost of Sales | C7: 5920.509 | D7: 6167.176 | E7: 5901.4 | F7: 7769.9
B8: Gross Profit | C8: =C6-C7 -> 4498.785 | D8: =D6-D7 -> 4997.816 | E8: =E6-E7 -> 5300.9 | F8: =F6-F7 -> 3922.7
B9: Gross Margin % | C9: =C8/C6 -> 0.43177446 | D9: =D8/D6 -> 0.44763274 | E9: =E8/E6 -> 0.47319747 | F9: =F8/F6 -> 0.33548569
B10: Selling, General & Administrative Expense | C10: 2236.009 | D10: 2436.508 | E10: 2373.6 | F10: 2460.6
B11: Business Realignment & Other Operating Costs, Net | C11: 1.989 | D11: 0.441 | E11: 29.1 | F11: 20.6
B12: Operating Profit (EBIT) | C12: =C8-C10-C11 -> 2260.787 | D12: =D8-D10-D11 -> 2560.867 | E12: =E8-E10-E11 -> 2898.2 | F12: =F8-F10-F11 -> 1441.5
B13: Operating Margin % | C13: =C12/C6 -> 0.21698082 | D13: =D12/D6 -> 0.22936577 | E13: =E12/E6 -> 0.25871473 | F13: =F12/F6 -> 0.1232831
B14: Interest Expense, Net | C14: 137.557 | D14: 151.785 | E14: 165.7 | F14: 190.2
B15: Other (Income) Expense, Net | C15: 206.159 | D15: 237.218 | E15: 258.6 | F15: 37.1
B16: Income Before Income Taxes | C16: =C12-C14-C15 -> 1917.071 | D16: =D12-D14-D15 -> 2171.864 | E16: =E12-E14-E15 -> 2473.9 | F16: =F12-F14-F15 -> 1214.2
B17: Provision for Income Taxes | C17: 272.254 | D17: 310.077 | E17: 252.7 | F17: 330.9
B18: Effective Tax Rate % | C18: =C17/C16 -> 0.14201561 | D18: =D17/D16 -> 0.14276999 | E18: =E17/E16 -> 0.10214641 | F18: =F17/F16 -> 0.27252512
B19: Net Income | C19: =C16-C17 -> 1644.817 | D19: =D16-D17 -> 1861.787 | E19: =E16-E17 -> 2221.2 | F19: =F16-F17 -> 883.3
B20: Net Margin % | C20: =C19/C6 -> 0.15786262 | D20: =D19/D6 -> 0.1667522 | E20: =E19/E6 -> 0.19828071 | F20: =F19/F6 -> 0.075543506
B22: Diluted Earnings Per Share | C22: 7.96 | D22: 9.06 | E22: 10.92 | F22: 4.34
B23: Diluted Weighted-Average Shares Outstanding | C23: 206.575 | D23: 205.547 | E23: 203.5 | F23: 203.4
B25: Supplemental — EBITDA & Growth
B26: Depreciation & Amortization | C26: ='Cash Flow Statement'!C8 -> 379 | D26: ='Cash Flow Statement'!D8 -> 420 | E26: ='Cash Flow Statement'!E8 -> 455 | F26: ='Cash Flow Statement'!F8 -> 504
B27: EBITDA (EBIT + D&A) | C27: =C12+C26 -> 2639.787 | D27: =D12+D26 -> 2980.867 | E27: =E12+E26 -> 3353.2 | F27: =F12+F26 -> 1945.5
B28: EBITDA Margin % | C28: =C27/C6 -> 0.25335565 | D28: =D27/D6 -> 0.26698335 | E28: =E27/E6 -> 0.29933139 | F28: =F27/F6 -> 0.16638729
B29: Net Sales YoY Growth % (n/a for FY2022A, first year shown) | C29: n/a | D29: =(D6/C6)-1 -> 0.071568957 | E29: =(E6/D6)-1 -> 0.0033415161 | F29: =(F6/E6)-1 -> 0.043767798

Sheet Balance Sheet
B2: Balance Sheet — Historical Actuals
B3: $ in millions. As of fiscal year-end (December 31).
C5: FY2023A | D5: FY2024A | E5: FY2025A
B6: Assets
B7: Cash & Cash Equivalents | C7: 401.9 | D7: 730.75 | E7: 925.86
B8: Accounts Receivable, Net | C8: 823.62 | D8: 800.4 | E8: 729.55
B9: Inventory | C9: 1341 | D9: 1254 | E9: 1429
B10: Other Current Assets | C10: 345.59 | D10: 974.21 | E10: 504.24
B11: Total Current Assets | C11: =SUM(C7:C10) -> 2912.11 | D11: =SUM(D7:D10) -> 3759.36 | E11: =SUM(E7:E10) -> 3588.65
B12: Property, Plant & Equipment, Net | C12: 3618 | D12: 3797 | E12: 3855
B13: Goodwill | C13: 2696 | D13: 2706 | E13: 2996
B14: Other Intangible Assets, Net | C14: 2239 | D14: 2241 | E14: 2827
B15: Other Long-Term Assets | C15: 438 | D15: 444 | E15: 474
B16: Total Assets | C16: =C11+C12+C13+C14+C15 -> 11903.11 | D16: =D11+D12+D13+D14+D15 -> 12947.36 | E16: =E11+E12+E13+E14+E15 -> 13740.65
B18: Liabilities
B19: Accounts Payable | C19: 1086 | D19: 1159 | E19: 1256
B20: Short-Term Debt (current portion) | C20: 719.84 | D20: 1307 | E20: 218.55
B21: Other Current Liabilities | C21: 1202.16 | D21: 1463 | E21: 1539.45
B22: Total Current Liabilities | C22: =SUM(C19:C21) -> 3008 | D22: =SUM(D19:D21) -> 3929 | E22: =SUM(E19:E21) -> 3014
B23: Long-Term Debt | C23: 3719 | D23: 3122 | E23: 4612
B24: Deferred Tax Liabilities | C24: 345.7 | D24: 424.24 | E24: 679.54
B25: Other Long-Term Liabilities | C25: 732.3 | D25: 756.47 | E25: 789.84
B26: Total Liabilities | C26: =C22+C23+C24+C25 -> 7805 | D26: =D22+D23+D24+D25 -> 8231.71 | E26: =E22+E23+E24+E25 -> 9095.38
B28: Stockholders' Equity
B29: Total Stockholders' Equity | C29: 4099 | D29: 4715 | E29: 4637
B30: Total Liabilities & Stockholders' Equity | C30: =C26+C29 -> 11904 | D30: =D26+D29 -> 12946.71 | E30: =E26+E29 -> 13732.38
B32: Balance Check (Total Assets − Total Liab. & Equity) | C32: =C16-C30 -> -0.89 | D32: =D16-D30 -> 0.65 | E32: =E16-E30 -> 8.27 | F32: Should be ~0. Small residual reflects rounding in the secondary source, not a broken formula.
B35: Credit & Liquidity Ratios (calculate using figures above and EBITDA from the Income Statement tab)
B36: Current Ratio (Current Assets / Current Liabilities) | C36: =C11/C22 -> 0.96812168 | D36: =D11/D22 -> 0.95682362 | E36: =E11/E22 -> 1.1906603
B37: Total Debt (Short-Term + Long-Term) | C37: =C20+C23 -> 4438.84 | D37: =D20+D23 -> 4429 | E37: =E20+E23 -> 4830.55
B38: Net Debt / EBITDA | C38: =(C37-C11)/'Income Statement'!C27 -> 0.57835348 | D38: =(D37-D11)/'Income Statement'!D27 -> 0.22464605 | E38: =(E37-E11)/'Income Statement'!E27 -> 0.37036264
B39: Total Debt / Total Equity | C39: =C37/C29 -> 1.082908 | D39: =D37/D29 -> 0.93934252 | E39: =E37/E29 -> 1.0417403

Sheet Cash Flow Statement
B2: Cash Flow Statement — Historical Actuals
B3: $ in millions. FY = fiscal year ended December 31.
C5: FY2022A | D5: FY2023A | E5: FY2024A | F5: FY2025A
B6: Operating Activities
B7: Net Income | C7: 1644.817 | D7: 1861.787 | E7: 2221.2 | F7: 883.3
B8: Depreciation & Amortization | C8: 379 | D8: 420 | E8: 455 | F8: 504
B9: Stock-Based Compensation | C9: 66 | D9: 81 | E9: 44 | F9: 65
B10: Change in Net Working Capital & Other Operating Items | C10: -108 | D10: -369 | E10: -69 | F10: 40
B11: Cash Flow from Operating Activities (as reported) | C11: 2328 | D11: 2323 | E11: 2532 | F11: 2277
B13: Investing Activities
B14: Capital Expenditures | C14: -519 | D14: -771 | E14: -606 | F14: -455
B15: Acquisitions, Net of Cash Acquired | C15: 0 | D15: -166 | E15: -76 | F15: -756
B16: Cash Flow from Investing Activities (as reported) | C16: -787 | D16: -1199 | E16: -960 | F16: -1279
B18: Financing Activities
B19: Dividends Paid | C19: -775 | D19: -889 | E19: -1085 | F19: -1085
B20: Share Repurchases | C20: -424 | D20: -300 | E20: -527 | F20: -19
B21: Net Debt Issued / (Repaid) | C21: -250 | D21: 15 | E21: 301 | F21: 279
B22: Cash Flow from Financing Activities (as reported) | C22: -1416 | D22: -1148 | E22: -1297 | F22: -803
B24: Net Change in Cash (calculated) | C24: =C11+C16+C22 -> 125 | D24: =D11+D16+D22 -> -24 | E24: =E11+E16+E22 -> 275 | F24: =F11+F16+F22 -> 195
B25: As reported (for reference): FY22 +$135mm · FY23 −$62mm · FY24 +$329mm · FY25 +$195mm. Small variance vs. the calculated line above reflects FX and rounding in the secondary source.
B27: Free Cash Flow (Unlevered Proxy) & Ratios
B28: Free Cash Flow (Cash from Ops − Capex) | C28: =C11+C14 -> 1809 | D28: =D11+D14 -> 1552 | E28: =E11+E14 -> 1926 | F28: =F11+F14 -> 1822
B29: FCF Margin % (FCF / Net Sales — see Income Statement tab) | C29: =C28/'Income Statement'!C6 -> 0.17362021 | D29: =D28/'Income Statement'!D6 -> 0.13900592 | E29: =E28/'Income Statement'!E6 -> 0.17192898 | F29: =F28/'Income Statement'!F6 -> 0.15582505
B30: FCF Conversion % (FCF / EBITDA — see Income Statement tab) | C30: =C28/'Income Statement'!C27 -> 0.68528256 | D30: =D28/'Income Statement'!D27 -> 0.52065389 | E30: =E28/'Income Statement'!E27 -> 0.57437671 | F30: =F28/'Income Statement'!F27 -> 0.93652017

Sheet DCF Model
B2: DCF Model — Unlevered Free Cash Flow Valuation
B3: $ in millions except per-share data. Yellow cells are your assumptions; everything else recalculates automatically.
C5: FY2025A | D5: FY2026E | E5: FY2027E | F5: FY2028E | G5: FY2029E | H5: FY2030E
B6: Revenue Build
B7: Net Sales | C7: ='Income Statement'!F6 -> 11692.6 | D7: =C7*(1+D8) -> 12335.693 | E7: =D7*(1+E8) -> 13014.156 | F7: =E7*(1+F8) -> 13729.935 | G7: =F7*(1+G8) -> 14485.081 | H7: =G7*(1+H8) -> 15281.761
B8: Net Sales Growth % (your assumption) | D8: 0.055 | E8: 0.055 | F8: 0.055 | G8: 0.055 | H8: 0.055
B10: Margin & Tax Assumptions
B11: EBITDA Margin % (your assumption) | D11: 0.247 | E11: 0.247 | F11: 0.247 | G11: 0.247 | H11: 0.247
B12: EBITDA | D12: =D7*D11 -> 3046.9162 | E12: =E7*E11 -> 3214.4966 | F12: =F7*F11 -> 3391.2939 | G12: =G7*G11 -> 3577.815 | H12: =H7*H11 -> 3774.5949
B13: D&A % of Net Sales (your assumption) | D13: 0.039 | E13: 0.039 | F13: 0.039 | G13: 0.039 | H13: 0.039
B14: Less: Depreciation & Amortization | D14: =-D7*D13 -> -481.09203 | E14: =-E7*E13 -> -507.55209 | F14: =-F7*F13 -> -535.46745 | G14: =-G7*G13 -> -564.91816 | H14: =-H7*H13 -> -595.98866
B15: EBIT | D15: =D12+D14 -> 2565.8241 | E15: =E12+E14 -> 2706.9445 | F15: =F12+F14 -> 2855.8264 | G15: =G12+G14 -> 3012.8969 | H15: =H12+H14 -> 3178.6062
B16: Tax Rate (linked from Assumptions tab) | D16: =Assumptions!$C$24 -> 0.165 | E16: =Assumptions!$C$24 -> 0.165 | F16: =Assumptions!$C$24 -> 0.165 | G16: =Assumptions!$C$24 -> 0.165 | H16: =Assumptions!$C$24 -> 0.165
B17: Less: Taxes on EBIT | D17: =-D15*D16 -> -423.36098 | E17: =-E15*E16 -> -446.64584 | F17: =-F15*F16 -> -471.21136 | G17: =-G15*G16 -> -497.12798 | H17: =-H15*H16 -> -524.47002
B18: NOPAT (Tax-Effected EBIT) | D18: =D15+D17 -> 2142.4632 | E18: =E15+E17 -> 2260.2986 | F18: =F15+F17 -> 2384.6151 | G18: =G15+G17 -> 2515.7689 | H18: =H15+H17 -> 2654.1362
B20: Unlevered Free Cash Flow Build
B21: Plus: Depreciation & Amortization | D21: =-D14 -> 481.09203 | E21: =-E14 -> 507.55209 | F21: =-F14 -> 535.46745 | G21: =-G14 -> 564.91816 | H21: =-H14 -> 595.98866
B22: Capex % of Net Sales (your assumption) | D22: 0.053 | E22: 0.053 | F22: 0.053 | G22: 0.053 | H22: 0.053
B23: Less: Capital Expenditures | D23: =-D7*D22 -> -653.79173 | E23: =-E7*E22 -> -689.75027 | F23: =-F7*F22 -> -727.68654 | G23: =-G7*G22 -> -767.7093 | H23: =-H7*H22 -> -809.93331
B24: Increase in Net Working Capital, % of Net Sales (your assumption) | D24: 0.0115 | E24: 0.0115 | F24: 0.0115 | G24: 0.0115 | H24: 0.0115
B25: Less: Increase in Net Working Capital | D25: =-D7*D24 -> -141.86047 | E25: =-E7*E24 -> -149.6628 | F25: =-F7*F24 -> -157.89425 | G25: =-G7*G24 -> -166.57843 | H25: =-H7*H24 -> -175.74025
B26: Unlevered Free Cash Flow | D26: =D18+D21+D23+D25 -> 1827.903 | E26: =E18+E21+E23+E25 -> 1928.4377 | F26: =F18+F21+F23+F25 -> 2034.5017 | G26: =G18+G21+G23+G25 -> 2146.3993 | H26: =H18+H21+H23+H25 -> 2264.4513
B28: Discounting
B29: WACC (linked from Assumptions tab) | D29: =Assumptions!$C$28 -> 0.064629218 | E29: =Assumptions!$C$28 -> 0.064629218 | F29: =Assumptions!$C$28 -> 0.064629218 | G29: =Assumptions!$C$28 -> 0.064629218 | H29: =Assumptions!$C$28 -> 0.064629218
B30: Discount Period (years) | D30: 1 | E30: 2 | F30: 3 | G30: 4 | H30: 5
B31: Discount Factor | D31: =1/(1+D29)^D30 -> 0.93929415 | E31: =1/(1+E29)^E30 -> 0.88227351 | F31: =1/(1+F29)^F30 -> 0.82871435 | G31: =1/(1+G29)^G30 -> 0.77840654 | H31: =1/(1+H29)^H30 -> 0.73115271
B32: PV of Unlevered Free Cash Flow | D32: =D26*D31 -> 1716.9386 | E32: =E26*E31 -> 1701.4095 | F32: =F26*F31 -> 1686.0208 | G32: =G26*G31 -> 1670.7713 | H32: =H26*H31 -> 1655.6597
B34: Terminal Value
B35: Terminal Growth Rate (your assumption) | E35: 0.025
B36: Terminal Value — Gordon Growth (last year FCF) | H36: =IFERROR(H26*(1+$E$35)/(Assumptions!$C$28-$E$35),0) -> 58569.477
B37: PV of Terminal Value — Gordon Growth | H37: =H36*H31 -> 42823.232
B39: Exit EV/EBITDA Multiple (your assumption) | E39: 15
B40: Terminal Value — Exit Multiple (last year EBITDA x multiple) | H40: =H12*$E$39 -> 56618.923
B41: PV of Terminal Value — Exit Multiple | H41: =H40*H31 -> 41397.079
B43: Valuation Summary
B44: Sum of PV of Explicit-Period Unlevered FCF | C44: =SUM(D32:H32) -> 8430.7998
B45: Enterprise Value — Gordon Growth Method | C45: =C44+H37 -> 51254.032
B46: Enterprise Value — Exit Multiple Method | C46: =C44+H41 -> 49827.879
B47: Less: Net Debt (linked from Assumptions tab) | C47: =-Assumptions!$C$15 -> -3904.69
B48: Equity Value — Gordon Growth Method | C48: =C45+C47 -> 47349.342
...

Sheet LBO Model
B2: LBO Model — Leveraged Buyout Analysis
B3: $ in millions except per-share and multiple data. Yellow cells are your assumptions; everything else recalculates automatically. 5-year hold assumed.
C5: Year 0 (Entry) | D5: Year 1 | E5: Year 2 | F5: Year 3 | G5: Year 4 | H5: Year 5 (Exit)
B6: Entry / Transaction Assumptions
B7: LTM EBITDA at Entry (FY2025A, linked from Income Statement tab) | C7: ='Income Statement'!F27 -> 1945.5
B8: Entry EV / EBITDA Multiple (your assumption) | C8: 19
B9: Purchase Enterprise Value | C9: =C7*C8 -> 36964.5
B10: Transaction Fees, % of Enterprise Value (your assumption) | C10: 0.004
B11: Transaction Fees, $ | C11: =C9*C10 -> 147.858
B13: Sources & Uses
B14: Uses: Purchase of Enterprise Value | C14: =C9 -> 36964.5
B15: Uses: Transaction Fees | C15: =C11 -> 147.858
B16: Total Uses | C16: =C14+C15 -> 37112.358
B18: Leverage — New Debt / LTM EBITDA (your assumption) | C18: 4
B19: Sources: New Debt (Term Loan) | C19: =C7*C18 -> 7782
B20: Sources: Sponsor Equity Contribution (plug) | C20: =C16-C19 -> 29330.358
B21: Total Sources (check — should equal Total Uses) | C21: =C19+C20 -> 37112.358
B23: Operating & Debt Assumptions (applied to each projection year)
B24: Interest Rate on Debt (your assumption) | C24: 0.1025
B25: Cash Tax Rate (linked from Assumptions tab) | C25: =Assumptions!$C$24 -> 0.165
B26: Capex, % of EBITDA (your assumption) | C26: 0.2175
B27: Increase in NWC, % of EBITDA (your assumption) | C27: 0.0412
B28: Mandatory Debt Amortization, % of Original Principal per Year (your assumption) | C28: 0.03
B29: Cash Flow Sweep, % of Excess Cash Flow to Debt Paydown (your assumption) | C29: 0.7
B31: EBITDA Build
B32: EBITDA Growth % (your assumption, per year) | D32: 0.06 | E32: 0.06 | F32: 0.06 | G32: 0.06 | H32: 0.06
B33: EBITDA | C33: =C7 -> 1945.5 | D33: =C33*(1+D32) -> 2062.23 | E33: =D33*(1+E32) -> 2185.9638 | F33: =E33*(1+F32) -> 2317.1216 | G33: =F33*(1+G32) -> 2456.1489 | H33: =G33*(1+H32) -> 2603.5179
B35: Free Cash Flow Available for Debt Paydown
B36: EBITDA | D36: =D33 -> 2062.23 | E36: =E33 -> 2185.9638 | F36: =F33 -> 2317.1216 | G36: =G33 -> 2456.1489 | H36: =H33 -> 2603.5179
B37: Less: Capex | D37: =-D33*$C$26 -> -448.53503 | E37: =-E33*$C$26 -> -475.44713 | F37: =-F33*$C$26 -> -503.97395 | G37: =-G33*$C$26 -> -534.21239 | H37: =-H33*$C$26 -> -566.26513
B38: Less: Cash Interest Expense (on beginning debt balance) | D38: =-D45*$C$24 -> -797.655 | E38: =-E45*$C$24 -> -746.67642 | F38: =-F45*$C$24 -> -687.14836 | G38: =-G45*$C$24 -> -618.22889 | H38: =-H45*$C$24 -> -539.00586
B39: Less: Increase in NWC | D39: =-D33*$C$27 -> -84.963876 | E39: =-E33*$C$27 -> -90.061709 | F39: =-F33*$C$27 -> -95.465411 | G39: =-G33*$C$27 -> -101.19334 | H39: =-H33*$C$27 -> -107.26494
B40: Pre-Tax Cash Flow | D40: =D36+D37+D38+D39 -> 731.0761 | E40: =E36+E37+E38+E39 -> 873.77854 | F40: =F36+F37+F38+F39 -> 1030.5339 | G40: =G36+G37+G38+G39 -> 1202.5143 | H40: =H36+H37+H38+H39 -> 1390.9819
B41: Less: Cash Taxes | D41: =-MAX(0,D40)*$C$25 -> -120.62756 | E41: =-MAX(0,E40)*$C$25 -> -144.17346 | F41: =-MAX(0,F40)*$C$25 -> -170.03809 | G41: =-MAX(0,G40)*$C$25 -> -198.41486 | H41: =-MAX(0,H40)*$C$25 -> -229.51202
B42: Cash Flow Available for Debt Service | D42: =D40+D41 -> 610.44854 | E42: =E40+E41 -> 729.60508 | F42: =F40+F41 -> 860.49581 | G42: =G40+G41 -> 1004.0994 | H42: =H40+H41 -> 1161.4699
B44: Debt Schedule
B45: Beginning Debt Balance | C45: =C19 -> 7782 | D45: =C19 -> 7782 | E45: =D48 -> 7284.648 | F45: =E48 -> 6703.8865 | G45: =F48 -> 6031.5014 | H45: =G48 -> 5258.5938
B46: Mandatory Amortization | D46: =-MIN($C$19*$C$28,D45) -> -233.46 | E46: =-MIN($C$19*$C$28,E45) -> -233.46 | F46: =-MIN($C$19*$C$28,F45) -> -233.46 | G46: =-MIN($C$19*$C$28,G45) -> -233.46 | H46: =-MIN($C$19*$C$28,H45) -> -233.46
B47: Cash Flow Sweep (excess CFADS after mandatory amort., capped at remaining balance) | D47: =-MIN(MAX(0,D42+D46)*$C$29,D45+D46) -> -263.89198 | E47: =-MIN(MAX(0,E42+E46)*$C$29,E45+E46) -> -347.30156 | F47: =-MIN(MAX(0,F42+F46)*$C$29,F45+F46) -> -438.92506 | G47: =-MIN(MAX(0,G42+G46)*$C$29,G45+G46) -> -539.44761 | H47: =-MIN(MAX(0,H42+H46)*$C$29,H45+H46) -> -649.60694
B48: Ending Debt Balance | D48: =MAX(0,D45+D46+D47) -> 7284.648 | E48: =MAX(0,E45+E46+E47) -> 6703.8865 | F48: =MAX(0,F45+F46+F47) -> 6031.5014 | G48: =MAX(0,G45+G46+G47) -> 5258.5938 | H48: =MAX(0,H45+H46+H47) -> 4375.5268
...
